<mujoco model="jaco2_ind_2">

    <!-- control visualizations -->
    <body name="hand_2" pos="0 0 -0.15" mocap="true">
        <geom type="box" size=".01 .02 .035" rgba="0 .9 0 .5" contype="2" conaffinity="2"/>
        <geom type="box" size=".001 .001 .02" pos="0.02 0 0" euler="0 -1.570796326794896 0" rgba=".9 0 0 .9" contype="8" conaffinity="8"/>
        <geom type="box" size=".001 .001 .02" pos="0 0.02 0" euler="-1.570796326794896 0 0" rgba=".0 9 0 .9" contype="8" conaffinity="8"/>
        <geom type="box" size=".001 .001 .02" pos="0 0 0.02" rgba=".0 0 9 .9" contype="8" conaffinity="8"/>
    </body>
    <body name="target_dest_2" pos="0 0 -0.15" mocap="true">
        <geom name="target" type="sphere" size="0.025" rgba=".9 0 0 .5" contype="4" conaffinity="4"/>
    </body>
    <body name="target_reach_2" pos="0 0 -0.15" mocap="true">
        <geom type="box" size=".01 .02 .03" rgba=".9 0 0 .5" contype="8" conaffinity="8"/>
        <geom type="box" size=".001 .001 .02" pos="0.02 0 0" euler="0 -1.570796326794896 0" rgba=".9 0 0 .9" contype="8" conaffinity="8"/>
        <geom type="box" size=".001 .001 .02" pos="0 0.02 0" euler="-1.570796326794896 0 0" rgba=".0 9 0 .9" contype="8" conaffinity="8"/>
        <geom type="box" size=".001 .001 .02" pos="0 0 0.02" rgba=".0 0 9 .9" contype="8" conaffinity="8"/>
    </body>

    <!-- <body name="base_link_2" pos="0.5 1.2 0" euler='0 0 3.141592'> -->
    <body name="base_link_2" pos="0.5 0 0">
            <geom name="link0_2" type="mesh" mesh="link0" pos="0 0 0" material="carbon"/>
            <inertial pos="0.000000 0.000000 0.125500" mass="1.226" diaginertia="0.25 0.25 0.25"/>
            <geom type="sphere" size="0.025" pos="0.000000 0.000000 0.125500" rgba="1 0.5 0 1"/>

            <body name="link1_2" pos="0 0 0.157">
                <inertial pos="-0.000042 -0.001285 0.112784" mass="0.754000" diaginertia="0.3 0.3 0.3"/>
                <geom name="link1_2" type="mesh" mesh="link1" pos="0 0 0" euler="0 3.14 0" material="carbon"/>
                <!--<geom name="ring0" type="mesh" mesh="ring_big_joint0" material="grey_plastic"/>-->
                <joint name="joint0_2" axis="0 0 -1" pos="0 0 0"/>

                <body name="link2_2" pos="0 0.0016 0.1186">
                    <inertial pos="0.000014 0.009353 0.329006" mass="1.010000" diaginertia="0.3 0.3 0.3"/>
                    <geom name="link2_2" type="mesh" mesh="link2" pos="0 0 0" euler="1.57 0 3.14" material="carbon"/>
                    <geom name="ring1_2" type="mesh" mesh="ring_big" material="grey_plastic" euler="1.57 0 0"/>
                    <joint name="joint1_2" pos="0 0 0" axis="0 -1 0"  ref="3.14" limited="true" range="0.872665 5.41052"/>

                    <body name="link3_2" pos="0 0 0.410">
                        <inertial pos="-0.000039 -0.018069 0.153270" mass="0.559000" diaginertia="0.275 0.275 0.275"/>
                        <geom name="link3_2" type="mesh" mesh="link3" pos="0 0 0" euler="1.57 3.14 0" material="carbon"/>
                        <geom name="ring2_2" type="mesh" mesh="ring_big" material="grey_plastic" euler="1.57 0 0"/>
                        <joint name="joint2_2" pos="0 0 0" axis="0 1 0" ref="3.14" limited="true" range="0.331613 5.95157"/>

                        <body name="link4_2" pos="0 -0.0115 0.2072">
                            <inertial pos="0.000000 0.032302 0.059705" mass="0.417000" diaginertia="0.175 0.175 0.175"/>
                            <geom name="link4_2" type="mesh" mesh="link4_5" euler="3.14 0 0" material="carbon"/>
                            <geom name="ring3_2" type="mesh" mesh="ring_small" material="grey_plastic"/>
                            <joint name="joint3_2" pos="0 0 0" axis="0 0 -1" ref="0"/>

                            <body name="link5_2" pos="0 0.037 0.0641">
                                <inertial pos="-0.000000 0.035545 0.057833" mass="0.417" diaginertia="0.175 0.175 0.175"/>
                                <geom name="link5_2" type="mesh" mesh="link4_5" euler="-1.0472 3.14 0" material="carbon"/>
                                <geom name="ring4_2" type="mesh" mesh="ring_small" material="grey_plastic" euler="-1.0471 0 0"/>
                                <joint name="joint4_2" pos="0 0 0" axis="0 -1.9 -1.1" ref="0"/>

                                <body name="link6_2" pos="0 0.037 0.0641">
                                    <inertial pos="0.000030 -0.006840 0.082220" mass="0.727000" diaginertia="0.025 0.025 0.025"/>
                                    <geom name="link6_2" type="mesh" mesh="hand_3finger" euler="3.14 0 0" material="carbon" solimp="0.97 0.97 0.01" solref="0.01 1" condim="6" />
                                    <site name="EE_touch_2" type="cylinder" size="0.07 0.05 0.1" euler="3.14 0 0" pos="0 0 0.065" rgba="0 0 1 0"/>
                                    <geom name="ring5_2" type="mesh" mesh="ring_small" material="grey_plastic"/>
                                    <joint name="joint5_2" pos="0 0 0" axis="0 0 -1" ref="0"/>

                                    <!-- for fingertip EE -->
                                    <!-- <body name="EE" pos="0 0 0.20222" euler="0 0 0"> -->
                                    <!-- </body> -->

                                    <!-- for palm EE -->
                                    <body name="EE_2" pos="0 0 0.12" euler="0 0 0">
                                        <body name="EE_obj_2" pos="0.04 0 0.04" euler="0 0 0"></body>
                                        <body name="xwise_2"  euler="0 1.570796326794896 0">
                                            <geom type="box" size=".001 .001 .02" pos="0 0 0.02"  rgba=".9 0 0 .9" contype="8" conaffinity="8"/>
                                        </body>
                                        <body name="ywise_2"  euler="-1.570796326794896 0 0">
                                            <geom type="box" size=".001 .001 .02" pos="0 0 0.02" rgba=".0 9 0 .9" contype="8" conaffinity="8"/>
                                        </body>
                                        <body name="zwise_2"  euler='0 0 0'>
                                            <geom type="box" size=".001 .001 .02" pos="0 0 0.02" rgba=".0 0 9 .9" contype="8" conaffinity="8"/>
                                        </body>
                                        <body name="palm_plane_2" pos="0 0 -0.002" euler="0 0 0" >
                                            <geom name="palm_plane_2" type="box" size="0.02 0.02 0.0005" rgba="0 1 0 0.5" />
                                            <site name="0_touch_2" type="box" size="0.02 0.02 0.0005" pos="0 0 0.001" rgba="0 0 1 0.5"/>
                                        </body>
                                    </body>

                                    <body name="thumb_proximal_2" pos="0.002786 -0.03126 0.114668" quat="0.95922726 0.262085 0.02762996 -0.10213274">
                                        <geom name="thumb_proximal_2" type="mesh" mesh="finger_proximal" euler="0 -1.5707 0" friction="1 0.5 0.01" solimp="0.95 0.95 0.01 0.5 6" solref="0.01 1" condim="6" margin="0.0"/>
                                        <!-- <joint name="joint_thumb" pos="0 0 0" axis="1 0 0" ref="1.1" limited="true" range="-0.2 1.1" solimplimit="0.95 0.95 0.01" solreflimit="0.01 1" stiffness="5" springref="0.0" damping="0.35"/>                                         -->
                                        <!-- <joint name="joint_thumb" pos="0 0 0" axis="1 0 0" ref="1.1" limited="true" range="0.35 1.1" solimplimit="0.95 0.95 0.01" solreflimit="0.01 1" stiffness="5" springref="0.0" damping="0.35"/> -->
                                        <joint name="joint_thumb_2" pos="0 0 0" axis="1 0 0" ref="1.1" limited="true" range="0 1.51" damping="0.15"/>
                                        <body name="thumb_outer_proximal_plane_2" pos="0 -0.021 0.022" euler="1.49 0 0">
                                            <geom name="thumb_outer_proximal_plane_2" type="box"  size="0.01 0.02 0.0005" rgba="0 1 0 0.5" />
                                            <site name="13_touch_2" type="box" pos="0 0 0.0010 " size="0.01 0.02 0.0005" rgba="0 0 1 0.5"/>
                                        </body>
                                        <body name="thumb_proximal_plane_2"  euler="1.44 0 0" pos="0 0.0035 0.032">
                                            <geom name="thumb_proximal_plane_2" type="box" size="0.01 0.02 0.0005" rgba="0 1 0 0.5" />
                                            <site name="1_touch_2" type="box" pos="0 0.0010 0.0" size="0.01 0.02 0.0005" rgba="0 0 1 0.5"/>
                                        </body>
                                        <body name="thumb_proximal_plane2_2" pos="0 0.0035 0.013" euler="1.7453 0 0">
                                            <geom name="thumb_proximal_plane2_2" type="box" size="0.01 0.02 0.0005" rgba="0 1 0 0.5" />
                                            <site name="2_touch_2" type="box" pos="0 0.0010 0.0" size="0.01 0.02 0.0005" rgba="0 0 1 0.5"/>
                                        </body>
                                        <body name="thumb_distal_2" pos="0 -0.0035 0.044" euler="-0.3 0 0">
                                            <geom name="thumb_distal_2" type="mesh" mesh="finger_distal" euler="0 -1.5707 0" friction="1 0.5 0.01" solimp="0.95 0.95 0.01 0.5 6" solref="0.01 1" condim="6" margin="0.0"/>
                                            <!-- <joint name="joint_thumb_distal" pos="0 0 0" axis="-1 0 0" ref="-0.5" limited="true" range="-0.4 0.4" stiffness="5" springref="-0.4" damping="0.5" solimplimit="0.95 0.95 0.01" solreflimit="0.01 1"/> -->
                                            <!-- <joint name="joint_thumb_distal" pos="0 0 0" axis="-1 0 0" limited="true" range="0 0.6981"/> -->
                                            <body name="thumb_outer_distal_plane_2" pos="0 -0.011 0.02" euler="1.42 0 0">
                                                <geom name="thumb_outer_distal_plane_2" type="box"  size="0.01 0.022 0.0005" rgba="0 1 0 0.5" />
                                                <site name="14_touch_2" type="box" pos="0 0 0.0010 " size="0.01 0.022 0.0005" rgba="0 0 1 0.5"/>
                                            </body>                                            
                                            <body name="thumb_distal_plane_2" pos="0 -0.0025 0.035">
                                                <geom name="thumb_distal_plane_2" type="box" euler="1.8325 0 0" size="0.01 0.008 0.0005" rgba="0 1 0 0.5" />
                                                <site name="3_touch_2" type="box" pos="0 0.001 0.0" size="0.01 0.008 0.0005" euler="1.8325 0 0" rgba="0 0 1 0.5"/>
                                            </body>
                                            <body name="thumb_distal_plane2_2" pos="0 0.0025 0.016">
                                                <geom name="thumb_distal_plane2_2" type="box" euler="1.9 0 0" size="0.01 0.008 0.0005" rgba="0 1 0 0.5" />
                                                <site name="4_touch_2" type="box" pos="0 0.001 0.0" size="0.01 0.008 0.0005" euler="1.9 0 0" rgba="0 0 1 0.5"/>
                                            </body>
                                        </body>
                                    </body>

                                    <body name="index_proximal_2" pos="0.022256 0.027073 0.114668" quat="0.96181018 -0.25771638 0.0238668 -0.08907205">
                                        <geom name="index_proximal_2" type="mesh" mesh="finger_proximal" quat="5.63312174e-04  7.06824957e-01 -5.62863772e-04  7.07388045e-01" friction="1 0.5 0.01" solimp="0.95 0.95 0.01 0.5 6" solref="0.01 1" condim="6" margin="0.0"/>
                                        <!-- <joint name="joint_index" pos="0 0 0" axis="-1 0 0" ref="1.1" limited="true" range="-0.2 1.1" solimplimit="0.95 0.95 0.01" solreflimit="0.01 1" stiffness="5" springref="0.0" damping="0.35"/> -->
                                        <!-- <joint name="joint_index" pos="0 0 0" axis="-1 0 0" ref="1.1" limited="true" range="0.35 1.1" solimplimit="0.95 0.95 0.01" solreflimit="0.01 1" stiffness="5" springref="0.0" damping="0.35"/> -->
                                        <joint name="joint_index_2" pos="0 0 0" axis="-1 0 0" ref="1.1" limited="true" range="0 1.51" damping="0.15"/>
                                        <body name="index_outer_proximal_plane_2" pos="0 0.021 0.022" euler="1.59 0 0">
                                            <geom name="index_outer_proximal_plane_2" type="box"  size="0.01 0.02 0.0005" rgba="0 1 0 0.5" />
                                            <site name="15_touch_2" type="box" pos="0 0 -0.0010" size="0.01 0.02 0.0005" rgba="0 0 1 0.5"/>
                                        </body>
                                        <body name="index_proximal_plane_2" pos="0 -0.0025 0.032">
                                            <geom name="index_proximal_plane_2" type="box" euler="1.7 0 0" size="0.01 0.02 0.0005" rgba="0 1 0 0.5" />
                                            <site name="5_touch_2" type="box" pos="0 -0.001 0.0" size="0.01 0.02 0.0005" euler="1.7 0 0" rgba="0 0 1 0.5"/>
                                        </body>
                                        <body name="index_proximal_plane2_2" pos="0 -0.0025 0.013">
                                            <geom name="index_proximal_plane2_2" type="box" euler="1.3963 0 0" size="0.01 0.02 0.0005" rgba="0 1 0 0.5" />
                                            <site name="6_touch_2" type="box" pos="0 -0.001 0.0" size="0.01 0.02 0.0005" euler="1.3963 0 0" rgba="0 0 1 0.5"/>
                                        </body>
                                        <body name="index_distal_2" pos="0 0.003 0.044" euler="0.3 0 0">
                                            <geom name="index_distal_2" type="mesh" mesh="finger_distal" quat="5.63312174e-04  7.06824957e-01 -5.62863772e-04  7.07388045e-01" friction="1 0.5 0.01" solimp="0.95 0.95 0.01 0.5 6" solref="0.01 1" condim="6" margin="0.0"/>
                                            <!-- <joint name="joint_index_distal" pos="0 0 0" axis="1 0 0" ref="-0.5" limited="true" range="-0.4 0.4" stiffness="5" springref="-0.4" damping="0.5" solimplimit="0.95 0.95 0.01" solreflimit="0.01 1"/> -->
                                            <!-- <joint name="joint_index_distal" pos="0 0 0" axis="1 0 0" limited="true" range="0 0.6981"/> -->
                                            <body name="index_outer_distal_plane_2" pos="0 0.012 0.02" euler="1.715 0 0">
                                                <geom name="index_outer_distal_plane_2" type="box"  size="0.01 0.022 0.0005" rgba="0 1 0 0.5" />
                                                <site name="16_touch_2" type="box" pos="0 0 -0.0010 " size="0.01 0.022 0.0005" rgba="0 0 1 0.5"/>
                                            </body> 
                                            <body name="index_distal_plane_2" pos="0 0.0025 0.035">
                                                <geom name="index_distal_plane_2" type="box" euler="1.309 0 0" size="0.01 0.008 0.0005" rgba="0 1 0 0.5" />
                                                <site name="7_touch_2" type="box" pos="0 -0.001 0.0" size="0.01 0.008 0.0005" euler="1.309 0 0" rgba="0 0 1 0.5"/>
                                            </body>
                                            <body name="index_distal_plane2_2" pos="0 -0.0035 0.016">
                                                <geom name="index_distal_plane2_2" type="box" euler="1.309 0 0" size="0.01 0.008 0.0005" rgba="0 1 0 0.5" />
                                                <site name="8_touch_2" type="box" pos="0 -0.001 0.0" size="0.01 0.008 0.0005" euler="1.309 0 0" rgba="0 0 1 0.5"/>
                                            </body>
                                        </body>
                                    </body>

                                    <body name="pinky_proximal_2" pos="-0.022256 0.027073 0.114816" quat="0.96181018 -0.25771638 -0.0238668 0.08907205">
                                        <geom name="pinky_proximal_2" type="mesh" mesh="finger_proximal" quat="5.63312174e-04  7.06824957e-01 -5.62863772e-04  7.07388045e-01" friction="1 0.5 0.01" solimp="0.95 0.95 0.01 0.5 6" solref="0.01 1" condim="6" margin="0.0"/>
                                        <!-- <joint name="joint_pinky" pos="0 0 0" axis="-1 0 0" ref="1.1" limited="true" range="-0.2 1.1" solimplimit="0.95 0.95 0.01" solreflimit="0.01 1" stiffness="5" springref="0.0" damping="0.35"/> -->
                                        <!-- <joint name="joint_pinky" pos="0 0 0" axis="-1 0 0" ref="1.1" limited="true" range="0.35 1.1" solimplimit="0.95 0.95 0.01" solreflimit="0.01 1" stiffness="5" springref="0.0" damping="0.35"/> -->
                                        <joint name="joint_pinky_2" pos="0 0 0" axis="-1 0 0" ref="1.1" limited="true" range="0 1.51" damping="0.15"/>
                                        <body name="pinky_outer_proximal_plane_2" pos="0 0.021 0.022" euler="1.59 0 0">
                                            <geom name="pinky_outer_proximal_plane_2" type="box"  size="0.01 0.02 0.0005" rgba="0 1 0 0.5" />
                                            <site name="17_touch_2" type="box" pos="0 0 -0.0010" size="0.01 0.02 0.0005" rgba="0 0 1 0.5"/>
                                        </body>
                                        <body name="pinky_proximal_plane_2" pos="0 -0.003 0.032">
                                            <geom name="pinky_proximal_plane_2" type="box" euler="1.7 0 0" size="0.01 0.02 0.0005" rgba="0 1 0 0.5" />
                                            <site name="9_touch_2" type="box" pos="0 -0.001 0.0" size="0.01 0.02 0.0005" euler="1.7 0 0" rgba="0 0 1 0.5"/>
                                        </body>
                                        <body name="pinky_proximal_plane2_2" pos="0 -0.0025 0.013">
                                            <geom name="pinky_proximal_plane2_2" type="box" euler="1.3963 0 0" size="0.01 0.02 0.0005" rgba="0 1 0 0.5" />
                                            <site name="10_touch_2" type="box" pos="0 -0.001 0.0" size="0.01 0.02 0.0005" euler="1.3963 0 0" rgba="0 0 1 0.5"/>
                                        </body>
                                        <body name="pinky_distal_2" pos="0 0.003 0.044" euler="0.3 0 0">
                                            <geom name="pinky_distal_2" type="mesh" mesh="finger_distal" quat="5.63312174e-04  7.06824957e-01 -5.62863772e-04  7.07388045e-01" friction="1 0.5 0.01" solimp="0.95 0.95 0.01 0.5 6" solref="0.01 1" condim="6" margin="0.0"/>
                                            <!-- <joint name="joint_pinky_distal" pos="0 0 0" axis="1 0 0" ref="0.2" limited="true" range="-0.4 0.4" stiffness="5" springref="0.4" damping="0.5" solimplimit="0.95 0.95 0.01" solreflimit="0.01 1"/> -->
                                            <!-- <joint name="joint_pinky_distal" pos="0 0 0" axis="1 0 0" limited="true" range="0 0.6981"/> -->
                                            <body name="pink_outer_distal_plane_2" pos="0 0.012 0.02" euler="1.715 0 0">
                                                <geom name="pink_outer_distal_plane_2" type="box"  size="0.01 0.022 0.0005" rgba="0 1 0 0.5" />
                                                <site name="18_touch_2" type="box" pos="0 0 -0.0010 " size="0.01 0.022 0.0005" rgba="0 0 1 0.5"/>
                                            </body> 
                                            <body name="pinky_distal_plane_2" pos="0 0.0025 0.035">
                                                <geom name="pinky_distal_plane_2" type="box" euler="1.309 0 0" size="0.01 0.008 0.0005" rgba="0 1 0 0.5" />
                                                <site name="11_touch_2" type="box" pos="0 -0.0008 0.0" size="0.01 0.008 0.0005" euler="1.309 0 0" rgba="0 0 1 0.5"/>
                                            </body>
                                            <body name="pinky_distal_plane2_2" pos="0 -0.0035 0.016">
                                                <geom name="pinky_distal_plane2_2" type="box" euler="1.309 0 0" size="0.01 0.008 0.0005" rgba="0 1 0 0.5" />
                                                <site name="12_touch_2" type="box" pos="0 -0.001 0.0" size="0.01 0.008 0.0005" euler="1.309 0 0" rgba="0 0 1 0.5"/>
                                            </body>
                                        </body>
                                    </body>
                                </body>
                            </body>
                        </body>
                    </body>
                </body>
            </body>
        </body>
</mujoco>
